Function calls with different errors don't unify.

SOURCE:
{
  fn foo1() -> Result<Int, ErrFoo> { Err(ErrFoo::A) }
  fn foo2() -> Result<Int, ErrFoo> { Err(ErrBar::X) }
  fn bar() -> Result<Int> {
    foo1()?;
    foo2()?;
    Ok(1)
  }
}

OUTPUT:
Type mismatch
Expected:
    Result<Int, ErrFoo>
Got:
    Result<Int, ErrBar>

3|    fn foo2() -> Result<Int, ErrFoo> { Err(ErrBar::X) }
                                         ^^^^^^^^^^^^^^